Traceback (most recent call last):
  File "/Users/nj.prem/Library/CloudStorage/OneDrive-KingMongkutâ€™sUniversityofTechnologyThonburi(KMUTT)/google it automation python/python_interact_with_OS/Python_Bash/./streams_err.py", line 5, in <module>
    raise ValueError("Now we generate an error to STDERR")
ValueError: Now we generate an error to STDERR
